<sdf version='1.7'>
  <world name='default'>
    <light name='sun' type='directional'>
      <cast_shadows>1</cast_shadows>
      <pose>0 0 10 0 -0 0</pose>
      <diffuse>0.8 0.8 0.8 1</diffuse>
      <specular>0.2 0.2 0.2 1</specular>
      <attenuation>
        <range>1000</range>
        <constant>0.9</constant>
        <linear>0.01</linear>
        <quadratic>0.001</quadratic>
      </attenuation>
      <direction>-0.5 0.1 -0.9</direction>
      <spot>
        <inner_angle>0</inner_angle>
        <outer_angle>0</outer_angle>
        <falloff>0</falloff>
      </spot>
    </light>
    <model name='ground_plane'>
      <static>1</static>
      <link name='link'>
        <collision name='collision'>
          <geometry>
            <plane>
              <normal>0 0 1</normal>
              <size>100 100</size>
            </plane>
          </geometry>
          <surface>
            <friction>
              <ode>
                <mu>100</mu>
                <mu2>50</mu2>
              </ode>
              <torsional>
                <ode/>
              </torsional>
            </friction>
            <contact>
              <ode/>
            </contact>
            <bounce/>
          </surface>
          <max_contacts>10</max_contacts>
        </collision>
        <visual name='visual'>
          <cast_shadows>0</cast_shadows>
          <geometry>
            <plane>
              <normal>0 0 1</normal>
              <size>100 100</size>
            </plane>
          </geometry>
          <material>
            <script>
              <uri>file://media/materials/scripts/gazebo.material</uri>
              <name>Gazebo/Grey</name>
            </script>
          </material>
        </visual>
        <self_collide>0</self_collide>
        <enable_wind>0</enable_wind>
        <kinematic>0</kinematic>
      </link>
    </model>
    <gravity>0 0 -9.8</gravity>
    <magnetic_field>6e-06 2.3e-05 -4.2e-05</magnetic_field>
    <atmosphere type='adiabatic'/>
    <physics type='ode'>
      <max_step_size>0.001</max_step_size>
      <real_time_factor>1</real_time_factor>
      <real_time_update_rate>1000</real_time_update_rate>
    </physics>
    <scene>
      <ambient>0.4 0.4 0.4 1</ambient>
      <background>0.7 0.7 0.7 1</background>
      <shadows>1</shadows>
    </scene>
    <audio>
      <device>default</device>
    </audio>
    <wind/>
    <spherical_coordinates>
      <surface_model>EARTH_WGS84</surface_model>
      <latitude_deg>0</latitude_deg>
      <longitude_deg>0</longitude_deg>
      <elevation>0</elevation>
      <heading_deg>0</heading_deg>
    </spherical_coordinates>
    <model name='box1'>
      <link name='link_0'>
        <inertial>
          <mass>0.0632298</mass>
          <inertia>
            <ixx>0.00127727</ixx>
            <ixy>0</ixy>
            <ixz>0</ixz>
            <iyy>0.00339237</iyy>
            <iyz>0</iyz>
            <izz>0.00298351</izz>
          </inertia>
          <pose>0 0 0 0 -0 0</pose>
        </inertial>
        <pose>0 0 0 0 -0 0</pose>
        <gravity>1</gravity>
        <self_collide>0</self_collide>
        <kinematic>0</kinematic>
        <enable_wind>0</enable_wind>
        <visual name='visual'>
          <pose>0 0 0 0 -0 0</pose>
          <geometry>
            <box>
              <size>0.69557 0.287062 0.4</size>
            </box>
          </geometry>
          <material>
            <lighting>1</lighting>
            <script>
              <uri>file://media/materials/scripts/gazebo.material</uri>
              <name>Gazebo/Grey</name>
            </script>
            <shader type='pixel'>
              <normal_map>__default__</normal_map>
            </shader>
            <ambient>1 0.3 0.3 1</ambient>
            <diffuse>1 0.7 0.7 1</diffuse>
            <specular>1 0.01 0.01 1</specular>
            <emissive>0 0 0 1</emissive>
          </material>
          <transparency>0</transparency>
          <cast_shadows>1</cast_shadows>
        </visual>
        <collision name='collision'>
          <laser_retro>0</laser_retro>
          <max_contacts>10</max_contacts>
          <pose>0 0 0 0 -0 0</pose>
          <geometry>
            <box>
              <size>0.69557 0.287062 0.4</size>
            </box>
          </geometry>
          <surface>
            <friction>
              <ode>
                <mu>1</mu>
                <mu2>1</mu2>
                <fdir1>0 0 0</fdir1>
                <slip1>0</slip1>
                <slip2>0</slip2>
              </ode>
              <torsional>
                <coefficient>1</coefficient>
                <patch_radius>0</patch_radius>
                <surface_radius>0</surface_radius>
                <use_patch_radius>1</use_patch_radius>
                <ode>
                  <slip>0</slip>
                </ode>
              </torsional>
            </friction>
            <bounce>
              <restitution_coefficient>0</restitution_coefficient>
              <threshold>1e+06</threshold>
            </bounce>
            <contact>
              <collide_without_contact>0</collide_without_contact>
              <collide_without_contact_bitmask>1</collide_without_contact_bitmask>
              <collide_bitmask>1</collide_bitmask>
              <ode>
                <soft_cfm>0</soft_cfm>
                <soft_erp>0.2</soft_erp>
                <kp>1e+13</kp>
                <kd>1</kd>
                <max_vel>0.01</max_vel>
                <min_depth>0</min_depth>
              </ode>
              <bullet>
                <split_impulse>1</split_impulse>
                <split_impulse_penetration_threshold>-0.01</split_impulse_penetration_threshold>
                <soft_cfm>0</soft_cfm>
                <soft_erp>0.2</soft_erp>
                <kp>1e+13</kp>
                <kd>1</kd>
              </bullet>
            </contact>
          </surface>
        </collision>
      </link>
      <static>0</static>
      <allow_auto_disable>1</allow_auto_disable>
      <pose>3.47781 1.38234 0 0 -0 0</pose>
    </model>
    <model name='limo_four_diff'>
      <link name='base_footprint'>
        <inertial>
          <pose>0.007905 0 0.160821 0 -0 0</pose>
          <mass>2.3657</mass>
          <inertia>
            <ixx>0.248941</ixx>
            <ixy>0</ixy>
            <ixz>-0.00196744</ixz>
            <iyy>0.970559</iyy>
            <iyz>0</iyz>
            <izz>0.961621</izz>
          </inertia>
        </inertial>
        <collision name='base_footprint_fixed_joint_lump__base_link_collision'>
          <pose>0 0 0.15 0 -0 0</pose>
          <geometry>
            <box>
              <size>0.13 0.12 0.1</size>
            </box>
          </geometry>
          <max_contacts>10</max_contacts>
          <surface>
            <contact>
              <ode/>
            </contact>
            <bounce/>
            <friction>
              <torsional>
                <ode/>
              </torsional>
              <ode/>
            </friction>
          </surface>
        </collision>
        <collision name='base_footprint_fixed_joint_lump__depth_camera_collision_collision_1'>
          <pose>0.084 0 0.015 0 -0 0</pose>
          <geometry>
            <box>
              <size>0.02 0.06 0.015</size>
            </box>
          </geometry>
          <max_contacts>10</max_contacts>
          <surface>
            <contact>
              <ode/>
            </contact>
            <bounce/>
            <friction>
              <torsional>
                <ode/>
              </torsional>
              <ode/>
            </friction>
          </surface>
        </collision>
        <collision name='base_footprint_fixed_joint_lump__imu_collision_collision_2'>
          <pose>0 0 0.05 0 -0 0</pose>
          <geometry>
            <box>
              <size>0.001 0.001 0.001</size>
            </box>
          </geometry>
          <max_contacts>10</max_contacts>
          <surface>
            <contact>
              <ode/>
            </contact>
            <bounce/>
            <friction>
              <torsional>
                <ode/>
              </torsional>
              <ode/>
            </friction>
          </surface>
        </collision>
        <collision name='base_footprint_fixed_joint_lump__laser_collision_collision_3'>
          <pose>0.103 0 0.116 0 -0 0</pose>
          <geometry>
            <cylinder>
              <length>0.016</length>
              <radius>0.032</radius>
            </cylinder>
          </geometry>
          <max_contacts>10</max_contacts>
          <surface>
            <contact>
              <ode/>
            </contact>
            <bounce/>
            <friction>
              <torsional>
                <ode/>
              </torsional>
              <ode/>
            </friction>
          </surface>
        </collision>
        <visual name='base_footprint_fixed_joint_lump__base_link_visual'>
          <pose>0 0 0 0 -0 1.57</pose>
          <geometry>
            <mesh>
              <scale>1 1 1</scale>
              <uri>model://limo_four_diff/meshes/limo_base.dae</uri>
            </mesh>
          </geometry>
        </visual>
        <visual name='base_footprint_fixed_joint_lump__depth_camera_visual_visual_1'>
          <pose>0.084 0 0.015 0 -0 0</pose>
          <geometry>
            <box>
              <size>0.02 0.06 0.015</size>
            </box>
          </geometry>
        </visual>
        <visual name='base_footprint_fixed_joint_lump__imu_visual_visual_2'>
          <pose>0 0 0.05 0 -0 0</pose>
          <geometry>
            <box>
              <size>0.001 0.001 0.001</size>
            </box>
          </geometry>
        </visual>
        <visual name='base_footprint_fixed_joint_lump__laser_visual_visual_3'>
          <pose>0.103 0 0.116 0 -0 0</pose>
          <geometry>
            <cylinder>
              <length>0.01</length>
              <radius>0.02</radius>
            </cylinder>
          </geometry>
        </visual>
        <sensor name='sensor_camera' type='depth'>
          <always_on>1</always_on>
          <visualize>1</visualize>
          <update_rate>30</update_rate>
          <camera name='limo_camera'>
            <distortion>
              <k1>0.1</k1>
              <k2>0.2</k2>
              <k3>0.3</k3>
              <p1>0.4</p1>
              <p2>0.5</p2>
              <center>0.5 0.5</center>
            </distortion>
            <horizontal_fov>1.047</horizontal_fov>
            <image>
              <width>320</width>
              <height>240</height>
            </image>
            <clip>
              <near>0.1</near>
              <far>100</far>
            </clip>
          </camera>
          <plugin name='gazebo_ros_depth_camera_sensor' filename='libgazebo_ros_camera.so'>
            <ros>
              <namespace>/limo</namespace>
              <argument>limo_camera/image_raw:=limo_camera/image</argument>
              <argument>limo_camera/image_depth:=limo_camera/depth/camera_image_depth</argument>
              <argument>limo_camera/camera_info:=limo_camera/camera_info_raw</argument>
              <argument>limo_camera/camera_info_depth:=limo_camera/camera_info_depth</argument>
              <argument>limo_camera/points:=limo_camera/camera_points</argument>
            </ros>
            <camera_name>depth_camera_link</camera_name>
            <frame_name>base_footprint</frame_name>
            <hack_baseline>0.07</hack_baseline>
            <min_depth>0.001</min_depth>
          </plugin>
          <pose>0.084 0 0.45 0 -0 0</pose>
        </sensor>
        <gravity>1</gravity>
        <sensor name='twr_imu' type='imu'>
          <always_on>1</always_on>
          <update_rate>100</update_rate>
          <visualize>1</visualize>
          <imu>
            <angular_velocity>
              <x>
                <noise type='gaussian'>
                  <mean>0</mean>
                  <stddev>0.0002</stddev>
                </noise>
              </x>
              <y>
                <noise type='gaussian'>
                  <mean>0</mean>
                  <stddev>0.0002</stddev>
                </noise>
              </y>
              <z>
                <noise type='gaussian'>
                  <mean>0</mean>
                  <stddev>0.0002</stddev>
                </noise>
              </z>
            </angular_velocity>
            <linear_acceleration>
              <x>
                <noise type='gaussian'>
                  <mean>0</mean>
                  <stddev>0.017</stddev>
                </noise>
              </x>
              <y>
                <noise type='gaussian'>
                  <mean>0</mean>
                  <stddev>0.017</stddev>
                </noise>
              </y>
              <z>
                <noise type='gaussian'>
                  <mean>0</mean>
                  <stddev>0.017</stddev>
                </noise>
              </z>
            </linear_acceleration>
            <orientation>
              <x>
                <noise type='gaussian'>
                  <mean>0.0</mean>
                  <stddev>2e-3</stddev>
                </noise>
              </x>
              <y>
                <noise type='gaussian'>
                  <mean>0.0</mean>
                  <stddev>2e-3</stddev>
                </noise>
              </y>
              <z>
                <noise type='gaussian'>
                  <mean>0.0</mean>
                  <stddev>2e-3</stddev>
                </noise>
              </z>
            </orientation>
          </imu>
          <plugin name='two_wheeled_robot_imu' filename='libgazebo_ros_imu_sensor.so'>
            <initial_orientation_as_reference>0</initial_orientation_as_reference>
            <frame_name>base_footprint</frame_name>
            <ros>
              <namespace>/imu</namespace>
              <remapping>~/out:=data</remapping>
            </ros>
          </plugin>
          <pose>0 0 0.05 0 -0 0</pose>
        </sensor>
        <sensor name='laser' type='ray'>
          <always_on>1</always_on>
          <visualize>1</visualize>
          <update_rate>10</update_rate>
          <ray>
            <scan>
              <horizontal>
                <samples>120</samples>
                <resolution>1</resolution>
                <min_angle>-3.14159</min_angle>
                <max_angle>3.14159</max_angle>
              </horizontal>
              <vertical>
                <samples>1</samples>
                <min_angle>0</min_angle>
                <max_angle>0</max_angle>
              </vertical>
            </scan>
            <range>
              <min>0.3</min>
              <max>15</max>
              <resolution>0.015</resolution>
            </range>
            <noise>
              <type>gaussian</type>
              <mean>0</mean>
              <stddev>0.01</stddev>
            </noise>
          </ray>
          <plugin name='scan' filename='libgazebo_ros_ray_sensor.so'>
            <ros>
              <remapping>~/out:=scan</remapping>
            </ros>
            <output_type>sensor_msgs/LaserScan</output_type>
            <frame_name>base_footprint</frame_name>
          </plugin>
          <pose>0.103 0 0.116 0 -0 0</pose>
        </sensor>
        <self_collide>0</self_collide>
        <enable_wind>0</enable_wind>
        <kinematic>0</kinematic>
      </link>
      <joint name='front_left_wheel' type='revolute'>
        <pose relative_to='base_footprint'>0.1 0.065 0.05 0 -0 0</pose>
        <parent>base_footprint</parent>
        <child>front_left_wheel_link</child>
        <axis>
          <xyz>0 1 0</xyz>
          <limit>
            <lower>-1e+16</lower>
            <upper>1e+16</upper>
          </limit>
          <dynamics>
            <spring_reference>0</spring_reference>
            <spring_stiffness>0</spring_stiffness>
          </dynamics>
        </axis>
        <physics>
          <ode>
            <limit>
              <cfm>0</cfm>
              <erp>0.2</erp>
            </limit>
          </ode>
        </physics>
      </joint>
      <link name='front_left_wheel_link'>
        <pose relative_to='front_left_wheel'>0 0 0 0 -0 0</pose>
        <inertial>
          <pose>0 0 0 0 -0 0</pose>
          <mass>0.5</mass>
          <inertia>
            <ixx>0.01055</ixx>
            <ixy>0</ixy>
            <ixz>0</ixz>
            <iyy>0.00075</iyy>
            <iyz>0</iyz>
            <izz>0.01055</izz>
          </inertia>
        </inertial>
        <collision name='front_left_wheel_link_collision'>
          <pose>0 0.0225 0 1.57 -0 0</pose>
          <geometry>
            <cylinder>
              <length>0.045</length>
              <radius>0.045</radius>
            </cylinder>
          </geometry>
          <max_contacts>10</max_contacts>
          <surface>
            <contact>
              <ode/>
            </contact>
            <bounce/>
            <friction>
              <torsional>
                <ode/>
              </torsional>
              <ode/>
            </friction>
          </surface>
        </collision>
        <visual name='front_left_wheel_link_visual'>
          <pose>0 0 0 0 -0 0</pose>
          <geometry>
            <mesh>
              <scale>1 1 1</scale>
              <uri>model://limo_four_diff/meshes/limo_wheel.dae</uri>
            </mesh>
          </geometry>
        </visual>
        <self_collide>0</self_collide>
        <enable_wind>0</enable_wind>
        <kinematic>0</kinematic>
      </link>
      <joint name='front_right_wheel' type='revolute'>
        <pose relative_to='base_footprint'>0.1 -0.065 0.05 3.14159 -0 0</pose>
        <parent>base_footprint</parent>
        <child>front_right_wheel_link</child>
        <axis>
          <xyz>0 -1 0</xyz>
          <limit>
            <lower>-1e+16</lower>
            <upper>1e+16</upper>
          </limit>
          <dynamics>
            <spring_reference>0</spring_reference>
            <spring_stiffness>0</spring_stiffness>
          </dynamics>
        </axis>
        <physics>
          <ode>
            <limit>
              <cfm>0</cfm>
              <erp>0.2</erp>
            </limit>
          </ode>
        </physics>
      </joint>
      <link name='front_right_wheel_link'>
        <pose relative_to='front_right_wheel'>0 0 0 0 -0 0</pose>
        <inertial>
          <pose>0 0 0 0 -0 0</pose>
          <mass>0.5</mass>
          <inertia>
            <ixx>0.01055</ixx>
            <ixy>0</ixy>
            <ixz>0</ixz>
            <iyy>0.00075</iyy>
            <iyz>0</iyz>
            <izz>0.01055</izz>
          </inertia>
        </inertial>
        <collision name='front_right_wheel_link_collision'>
          <pose>0 0.0225 0 1.57 -0 0</pose>
          <geometry>
            <cylinder>
              <length>0.045</length>
              <radius>0.045</radius>
            </cylinder>
          </geometry>
          <max_contacts>10</max_contacts>
          <surface>
            <contact>
              <ode/>
            </contact>
            <bounce/>
            <friction>
              <torsional>
                <ode/>
              </torsional>
              <ode/>
            </friction>
          </surface>
        </collision>
        <visual name='front_right_wheel_link_visual'>
          <pose>0 0 0 0 -0 0</pose>
          <geometry>
            <mesh>
              <scale>1 1 1</scale>
              <uri>model://limo_four_diff/meshes/limo_wheel.dae</uri>
            </mesh>
          </geometry>
        </visual>
        <self_collide>0</self_collide>
        <enable_wind>0</enable_wind>
        <kinematic>0</kinematic>
      </link>
      <joint name='rear_left_wheel' type='revolute'>
        <pose relative_to='base_footprint'>-0.1 0.065 0.05 0 -0 0</pose>
        <parent>base_footprint</parent>
        <child>rear_left_wheel_link</child>
        <axis>
          <xyz>0 1 0</xyz>
          <limit>
            <lower>-1e+16</lower>
            <upper>1e+16</upper>
          </limit>
          <dynamics>
            <spring_reference>0</spring_reference>
            <spring_stiffness>0</spring_stiffness>
          </dynamics>
        </axis>
        <physics>
          <ode>
            <limit>
              <cfm>0</cfm>
              <erp>0.2</erp>
            </limit>
          </ode>
        </physics>
      </joint>
      <link name='rear_left_wheel_link'>
        <pose relative_to='rear_left_wheel'>0 0 0 0 -0 0</pose>
        <inertial>
          <pose>0 0 0 0 -0 0</pose>
          <mass>0.5</mass>
          <inertia>
            <ixx>0.01055</ixx>
            <ixy>0</ixy>
            <ixz>0</ixz>
            <iyy>0.00075</iyy>
            <iyz>0</iyz>
            <izz>0.01055</izz>
          </inertia>
        </inertial>
        <collision name='rear_left_wheel_link_collision'>
          <pose>0 0.0225 0 1.57 -0 0</pose>
          <geometry>
            <cylinder>
              <length>0.045</length>
              <radius>0.045</radius>
            </cylinder>
          </geometry>
          <max_contacts>10</max_contacts>
          <surface>
            <contact>
              <ode/>
            </contact>
            <bounce/>
            <friction>
              <torsional>
                <ode/>
              </torsional>
              <ode/>
            </friction>
          </surface>
        </collision>
        <visual name='rear_left_wheel_link_visual'>
          <pose>0 0 0 0 -0 0</pose>
          <geometry>
            <mesh>
              <scale>1 1 1</scale>
              <uri>model://limo_four_diff/meshes/limo_wheel.dae</uri>
            </mesh>
          </geometry>
        </visual>
        <self_collide>0</self_collide>
        <enable_wind>0</enable_wind>
        <kinematic>0</kinematic>
      </link>
      <joint name='rear_right_wheel' type='revolute'>
        <pose relative_to='base_footprint'>-0.1 -0.065 0.05 3.14159 -0 0</pose>
        <parent>base_footprint</parent>
        <child>rear_right_wheel_link</child>
        <axis>
          <xyz>0 -1 0</xyz>
          <limit>
            <lower>-1e+16</lower>
            <upper>1e+16</upper>
          </limit>
          <dynamics>
            <spring_reference>0</spring_reference>
            <spring_stiffness>0</spring_stiffness>
          </dynamics>
        </axis>
        <physics>
          <ode>
            <limit>
              <cfm>0</cfm>
              <erp>0.2</erp>
            </limit>
          </ode>
        </physics>
      </joint>
      <link name='rear_right_wheel_link'>
        <pose relative_to='rear_right_wheel'>0 0 0 0 -0 0</pose>
        <inertial>
          <pose>0 0 0 0 -0 0</pose>
          <mass>0.5</mass>
          <inertia>
            <ixx>0.01055</ixx>
            <ixy>0</ixy>
            <ixz>0</ixz>
            <iyy>0.00075</iyy>
            <iyz>0</iyz>
            <izz>0.01055</izz>
          </inertia>
        </inertial>
        <collision name='rear_right_wheel_link_collision'>
          <pose>0 0.0225 0 1.57 -0 0</pose>
          <geometry>
            <cylinder>
              <length>0.045</length>
              <radius>0.045</radius>
            </cylinder>
          </geometry>
          <max_contacts>10</max_contacts>
          <surface>
            <contact>
              <ode/>
            </contact>
            <bounce/>
            <friction>
              <torsional>
                <ode/>
              </torsional>
              <ode/>
            </friction>
          </surface>
        </collision>
        <visual name='rear_right_wheel_link_visual'>
          <pose>0 0 0 0 -0 0</pose>
          <geometry>
            <mesh>
              <scale>1 1 1</scale>
              <uri>model://limo_four_diff/meshes/limo_wheel.dae</uri>
            </mesh>
          </geometry>
        </visual>
        <self_collide>0</self_collide>
        <enable_wind>0</enable_wind>
        <kinematic>0</kinematic>
      </link>
      <static>0</static>
      <plugin name='four_diff_controller' filename='libgazebo_ros_diff_drive.so'>
        <update_rate>50</update_rate>
        <num_wheel_pairs>2</num_wheel_pairs>
        <left_joint>front_left_wheel</left_joint>
        <right_joint>front_right_wheel</right_joint>
        <left_joint>rear_left_wheel</left_joint>
        <right_joint>rear_right_wheel</right_joint>
        <wheel_separation>0.172</wheel_separation>
        <wheel_diameter>0.09</wheel_diameter>
        <max_wheel_torque>20</max_wheel_torque>
        <max_wheel_acceleration>1.0</max_wheel_acceleration>
        <command_topic>cmd_vel</command_topic>
        <publish_odom>1</publish_odom>
        <publish_odom_tf>1</publish_odom_tf>
        <publish_wheel_tf>1</publish_wheel_tf>
        <odometry_topic>odom</odometry_topic>
        <odometry_frame>odom</odometry_frame>
        <robot_base_frame>base_footprint</robot_base_frame>
        <odometry_source>1</odometry_source>
        <ros>
          <remapping>odom:=/odometry</remapping>
        </ros>
      </plugin>
      <pose>1.90817 1.56297 0 0 -0 0</pose>
    </model>
    <state world_name='default'>
      <sim_time>259 767000000</sim_time>
      <real_time>309 529872532</real_time>
      <wall_time>1729756827 456187836</wall_time>
      <iterations>259767</iterations>
      <model name='box1'>
        <pose>3.47786 1.38247 0.199997 -2.3e-05 -0 0.000361</pose>
        <scale>1 1 1</scale>
        <link name='link_0'>
          <pose>3.47786 1.38247 0.199997 -2.3e-05 -0 0.000361</pose>
          <velocity>0 0 0 0 -0 0</velocity>
          <acceleration>0.858189 1.25982 -7.15928 3.13272 -1.15407 -3.13663</acceleration>
          <wrench>0.054263 0.079658 -0.45268 0 -0 0</wrench>
        </link>
      </model>
      <model name='ground_plane'>
        <pose>0 0 0 0 -0 0</pose>
        <scale>1 1 1</scale>
        <link name='link'>
          <pose>0 0 0 0 -0 0</pose>
          <velocity>0 0 0 0 -0 0</velocity>
          <acceleration>0 0 0 0 -0 0</acceleration>
          <wrench>0 0 0 0 -0 0</wrench>
        </link>
      </model>
      <model name='limo_four_diff'>
        <pose>1.91016 1.56004 -0.004982 1e-06 -1e-06 0.007966</pose>
        <scale>1 1 1</scale>
        <link name='base_footprint'>
          <pose>1.91016 1.56004 -0.004982 1e-06 -1e-06 0.007966</pose>
          <velocity>-2.1e-05 -1e-06 -1e-05 0.002104 0.00206 2.4e-05</velocity>
          <acceleration>0.096681 -0.395011 -0.393585 2.43972 0.241791 -0.073632</acceleration>
          <wrench>0.228718 -0.934476 -0.931104 0 -0 0</wrench>
        </link>
        <link name='front_left_wheel_link'>
          <pose>2.00963 1.62584 0.045018 0 0.036857 0.007966</pose>
          <velocity>8.7e-05 -0.0001 -2.5e-05 0.002232 0.001928 1e-05</velocity>
          <acceleration>0.042984 -0.135561 -0.001024 3.00453 0.629049 -0.006451</acceleration>
          <wrench>0.021492 -0.067781 -0.000512 0 -0 0</wrench>
        </link>
        <link name='front_right_wheel_link'>
          <pose>2.01067 1.49584 0.045018 3.14159 0.089073 0.007966</pose>
          <velocity>9.1e-05 -0.000138 -0.000319 0.002013 0.002059 2.4e-05</velocity>
          <acceleration>0.064382 -0.133068 -0.651952 2.36729 -0.012428 -0.07434</acceleration>
          <wrench>0.032191 -0.066534 -0.325976 0 -0 0</wrench>
        </link>
        <link name='rear_left_wheel_link'>
          <pose>1.80964 1.62424 0.045018 2e-06 -0.033759 0.007966</pose>
          <velocity>6.8e-05 -9.1e-05 0.000233 0.001967 0.002059 4.7e-05</velocity>
          <acceleration>0.032409 -0.079386 -0.60095 1.69462 1.0981 0.012803</acceleration>
          <wrench>0.016204 -0.039693 -0.300475 0 -0 0</wrench>
        </link>
        <link name='rear_right_wheel_link'>
          <pose>1.81068 1.49425 0.045018 3.14159 -0.069703 0.007966</pose>
          <velocity>7.4e-05 -9.7e-05 2.1e-05 0.002143 0.001647 2.5e-05</velocity>
          <acceleration>0.041911 -0.110342 -0.413161 2.44321 0.659246 -0.074426</acceleration>
          <wrench>0.020955 -0.055171 -0.206581 0 -0 0</wrench>
        </link>
      </model>
      <light name='sun'>
        <pose>0 0 10 0 -0 0</pose>
      </light>
    </state>
    <gui fullscreen='0'>
      <camera name='user_camera'>
        <pose>6.97773 -2.75718 2.66273 0 0.275643 2.35619</pose>
        <view_controller>orbit</view_controller>
        <projection_type>perspective</projection_type>
      </camera>
    </gui>
  </world>
</sdf>
