<sdf version='1.7'>
  <world name='default'>
    <light name='sun' type='directional'>
      <cast_shadows>1</cast_shadows>
      <pose>0 0 10 0 -0 0</pose>
      <diffuse>0.8 0.8 0.8 1</diffuse>
      <specular>0.2 0.2 0.2 1</specular>
      <attenuation>
        <range>1000</range>
        <constant>0.9</constant>
        <linear>0.01</linear>
        <quadratic>0.001</quadratic>
      </attenuation>
      <direction>-0.5 0.1 -0.9</direction>
      <spot>
        <inner_angle>0</inner_angle>
        <outer_angle>0</outer_angle>
        <falloff>0</falloff>
      </spot>
    </light>
    <model name='ground_plane'>
      <static>1</static>
      <link name='link'>
        <collision name='collision'>
          <geometry>
            <plane>
              <normal>0 0 1</normal>
              <size>100 100</size>
            </plane>
          </geometry>
          <surface>
            <friction>
              <ode>
                <mu>100</mu>
                <mu2>50</mu2>
              </ode>
              <torsional>
                <ode/>
              </torsional>
            </friction>
            <contact>
              <ode/>
            </contact>
            <bounce/>
          </surface>
          <max_contacts>10</max_contacts>
        </collision>
        <visual name='visual'>
          <cast_shadows>0</cast_shadows>
          <geometry>
            <plane>
              <normal>0 0 1</normal>
              <size>100 100</size>
            </plane>
          </geometry>
          <material>
            <script>
              <uri>file://media/materials/scripts/gazebo.material</uri>
              <name>Gazebo/Grey</name>
            </script>
          </material>
        </visual>
        <self_collide>0</self_collide>
        <enable_wind>0</enable_wind>
        <kinematic>0</kinematic>
      </link>
    </model>
    <physics type='ode'>
      <real_time_update_rate>1000</real_time_update_rate>
      <max_step_size>0.001</max_step_size>
      <real_time_factor>1</real_time_factor>
      <ode>
        <solver>
          <type>quick</type>
          <iters>150</iters>
          <precon_iters>0</precon_iters>
          <sor>1.4</sor>
          <use_dynamic_moi_rescaling>1</use_dynamic_moi_rescaling>
        </solver>
        <constraints>
          <cfm>1e-05</cfm>
          <erp>0.2</erp>
          <contact_max_correcting_vel>2000</contact_max_correcting_vel>
          <contact_surface_layer>0.01</contact_surface_layer>
        </constraints>
      </ode>
    </physics>
    <model name='turtlebot3_square'>
      <pose>0 0 0 0 -0 0</pose>
      <link name='Wall_0'>
        <collision name='Wall_0_Collision'>
          <geometry>
            <box>
              <size>4 0.15 0.5</size>
            </box>
          </geometry>
          <pose>0 0 0.25 0 -0 0</pose>
          <max_contacts>10</max_contacts>
          <surface>
            <contact>
              <ode/>
            </contact>
            <bounce/>
            <friction>
              <torsional>
                <ode/>
              </torsional>
              <ode/>
            </friction>
          </surface>
        </collision>
        <visual name='Wall_0_Visual'>
          <pose>0 0 0.25 0 -0 0</pose>
          <geometry>
            <box>
              <size>4 0.15 0.5</size>
            </box>
          </geometry>
          <material>
            <script>
              <uri>file://media/materials/scripts/gazebo.material</uri>
              <name>Gazebo/Wood</name>
            </script>
            <ambient>1 1 1 1</ambient>
          </material>
        </visual>
        <pose>0 1.925 0 0 -0 0</pose>
        <self_collide>0</self_collide>
        <enable_wind>0</enable_wind>
        <kinematic>0</kinematic>
      </link>
      <link name='Wall_2'>
        <collision name='Wall_2_Collision'>
          <geometry>
            <box>
              <size>4 0.15 0.5</size>
            </box>
          </geometry>
          <pose>0 0 0.25 0 -0 0</pose>
          <max_contacts>10</max_contacts>
          <surface>
            <contact>
              <ode/>
            </contact>
            <bounce/>
            <friction>
              <torsional>
                <ode/>
              </torsional>
              <ode/>
            </friction>
          </surface>
        </collision>
        <visual name='Wall_2_Visual'>
          <pose>0 0 0.25 0 -0 0</pose>
          <geometry>
            <box>
              <size>4 0.15 0.5</size>
            </box>
          </geometry>
          <material>
            <script>
              <uri>file://media/materials/scripts/gazebo.material</uri>
              <name>Gazebo/Wood</name>
            </script>
            <ambient>1 1 1 1</ambient>
          </material>
        </visual>
        <pose>-1.925 0 0 0 0 -1.5708</pose>
        <self_collide>0</self_collide>
        <enable_wind>0</enable_wind>
        <kinematic>0</kinematic>
      </link>
      <link name='Wall_3'>
        <collision name='Wall_3_Collision'>
          <geometry>
            <box>
              <size>4 0.15 0.5</size>
            </box>
          </geometry>
          <pose>0 0 0.25 0 -0 0</pose>
          <max_contacts>10</max_contacts>
          <surface>
            <contact>
              <ode/>
            </contact>
            <bounce/>
            <friction>
              <torsional>
                <ode/>
              </torsional>
              <ode/>
            </friction>
          </surface>
        </collision>
        <visual name='Wall_3_Visual'>
          <pose>0 0 0.25 0 -0 0</pose>
          <geometry>
            <box>
              <size>4 0.15 0.5</size>
            </box>
          </geometry>
          <material>
            <script>
              <uri>file://media/materials/scripts/gazebo.material</uri>
              <name>Gazebo/Wood</name>
            </script>
            <ambient>1 1 1 1</ambient>
          </material>
        </visual>
        <pose>0 -1.925 0 0 -0 0</pose>
        <self_collide>0</self_collide>
        <enable_wind>0</enable_wind>
        <kinematic>0</kinematic>
      </link>
      <link name='Wall_4'>
        <collision name='Wall_4_Collision'>
          <geometry>
            <box>
              <size>4 0.15 0.5</size>
            </box>
          </geometry>
          <pose>0 0 0.25 0 -0 0</pose>
          <max_contacts>10</max_contacts>
          <surface>
            <contact>
              <ode/>
            </contact>
            <bounce/>
            <friction>
              <torsional>
                <ode/>
              </torsional>
              <ode/>
            </friction>
          </surface>
        </collision>
        <visual name='Wall_4_Visual'>
          <pose>0 0 0.25 0 -0 0</pose>
          <geometry>
            <box>
              <size>4 0.15 0.5</size>
            </box>
          </geometry>
          <material>
            <script>
              <uri>file://media/materials/scripts/gazebo.material</uri>
              <name>Gazebo/Wood</name>
            </script>
            <ambient>1 1 1 1</ambient>
          </material>
        </visual>
        <pose>1.925 0 0 0 -0 1.5708</pose>
        <self_collide>0</self_collide>
        <enable_wind>0</enable_wind>
        <kinematic>0</kinematic>
      </link>
      <static>1</static>
    </model>
    <model name='obstacle'>
      <pose>0 0 0 0 -0 0</pose>
      <link name='obstacle'>
        <collision name='obstacle_1'>
          <pose>-0.6 -0.6 0.25 0 -0 0</pose>
          <geometry>
            <cylinder>
              <radius>0.15</radius>
              <length>0.5</length>
            </cylinder>
          </geometry>
          <max_contacts>10</max_contacts>
          <surface>
            <bounce/>
            <friction>
              <ode/>
              <torsional>
                <ode/>
              </torsional>
            </friction>
            <contact>
              <ode/>
            </contact>
          </surface>
        </collision>
        <visual name='obstacle_1'>
          <pose>-0.6 -0.6 0.25 0 -0 0</pose>
          <geometry>
            <cylinder>
              <radius>0.15</radius>
              <length>0.5</length>
            </cylinder>
          </geometry>
          <material>
            <script>
              <uri>file://media/materials/scripts/gazebo.material</uri>
              <name>Gazebo/White</name>
            </script>
          </material>
        </visual>
        <collision name='obstacle_2'>
          <pose>-0.6 0.6 0.25 0 -0 0</pose>
          <geometry>
            <cylinder>
              <radius>0.15</radius>
              <length>0.5</length>
            </cylinder>
          </geometry>
          <max_contacts>10</max_contacts>
          <surface>
            <bounce/>
            <friction>
              <ode/>
              <torsional>
                <ode/>
              </torsional>
            </friction>
            <contact>
              <ode/>
            </contact>
          </surface>
        </collision>
        <visual name='obstacle_2'>
          <pose>-0.6 0.6 0.25 0 -0 0</pose>
          <geometry>
            <cylinder>
              <radius>0.15</radius>
              <length>0.5</length>
            </cylinder>
          </geometry>
          <material>
            <script>
              <uri>file://media/materials/scripts/gazebo.material</uri>
              <name>Gazebo/White</name>
            </script>
          </material>
        </visual>
        <collision name='obstacle_3'>
          <pose>0.6 -0.6 0.25 0 -0 0</pose>
          <geometry>
            <cylinder>
              <radius>0.15</radius>
              <length>0.5</length>
            </cylinder>
          </geometry>
          <max_contacts>10</max_contacts>
          <surface>
            <bounce/>
            <friction>
              <ode/>
              <torsional>
                <ode/>
              </torsional>
            </friction>
            <contact>
              <ode/>
            </contact>
          </surface>
        </collision>
        <visual name='obstacle_3'>
          <pose>0.6 -0.6 0.25 0 -0 0</pose>
          <geometry>
            <cylinder>
              <radius>0.15</radius>
              <length>0.5</length>
            </cylinder>
          </geometry>
          <material>
            <script>
              <uri>file://media/materials/scripts/gazebo.material</uri>
              <name>Gazebo/White</name>
            </script>
          </material>
        </visual>
        <collision name='obstacle_4'>
          <pose>0.6 0.6 0.25 0 -0 0</pose>
          <geometry>
            <cylinder>
              <radius>0.15</radius>
              <length>0.5</length>
            </cylinder>
          </geometry>
          <max_contacts>10</max_contacts>
          <surface>
            <bounce/>
            <friction>
              <ode/>
              <torsional>
                <ode/>
              </torsional>
            </friction>
            <contact>
              <ode/>
            </contact>
          </surface>
        </collision>
        <visual name='obstacle_4'>
          <pose>0.6 0.6 0.25 0 -0 0</pose>
          <geometry>
            <cylinder>
              <radius>0.15</radius>
              <length>0.5</length>
            </cylinder>
          </geometry>
          <material>
            <script>
              <uri>file://media/materials/scripts/gazebo.material</uri>
              <name>Gazebo/White</name>
            </script>
          </material>
        </visual>
        <self_collide>0</self_collide>
        <enable_wind>0</enable_wind>
        <kinematic>0</kinematic>
      </link>
      <static>1</static>
    </model>
    <scene>
      <ambient>0.4 0.4 0.4 1</ambient>
      <background>0.7 0.7 0.7 1</background>
      <shadows>1</shadows>
    </scene>
    <gui fullscreen='0'>
      <camera name='user_camera'>
        <pose>-0.160045 -0.079889 5.30743 3.14159 1.57079 3.14159</pose>
        <view_controller>orbit</view_controller>
        <projection_type>perspective</projection_type>
      </camera>
    </gui>
    <gravity>0 0 -9.8</gravity>
    <magnetic_field>6e-06 2.3e-05 -4.2e-05</magnetic_field>
    <atmosphere type='adiabatic'/>
    <audio>
      <device>default</device>
    </audio>
    <wind/>
    <spherical_coordinates>
      <surface_model>EARTH_WGS84</surface_model>
      <latitude_deg>0</latitude_deg>
      <longitude_deg>0</longitude_deg>
      <elevation>0</elevation>
      <heading_deg>0</heading_deg>
    </spherical_coordinates>
    <model name='limo_four_diff'>
      <link name='base_footprint'>
        <inertial>
          <pose>0.007905 0 0.160821 0 -0 0</pose>
          <mass>2.3657</mass>
          <inertia>
            <ixx>0.248941</ixx>
            <ixy>0</ixy>
            <ixz>-0.00196744</ixz>
            <iyy>0.970559</iyy>
            <iyz>0</iyz>
            <izz>0.961621</izz>
          </inertia>
        </inertial>
        <collision name='base_footprint_fixed_joint_lump__base_link_collision'>
          <pose>0 0 0.15 0 -0 0</pose>
          <geometry>
            <box>
              <size>0.13 0.12 0.1</size>
            </box>
          </geometry>
          <max_contacts>10</max_contacts>
          <surface>
            <contact>
              <ode/>
            </contact>
            <bounce/>
            <friction>
              <torsional>
                <ode/>
              </torsional>
              <ode/>
            </friction>
          </surface>
        </collision>
        <collision name='base_footprint_fixed_joint_lump__depth_camera_collision_collision_1'>
          <pose>0.084 0 0.015 0 -0 0</pose>
          <geometry>
            <box>
              <size>0.02 0.06 0.015</size>
            </box>
          </geometry>
          <max_contacts>10</max_contacts>
          <surface>
            <contact>
              <ode/>
            </contact>
            <bounce/>
            <friction>
              <torsional>
                <ode/>
              </torsional>
              <ode/>
            </friction>
          </surface>
        </collision>
        <collision name='base_footprint_fixed_joint_lump__imu_collision_collision_2'>
          <pose>0 0 0.05 0 -0 0</pose>
          <geometry>
            <box>
              <size>0.001 0.001 0.001</size>
            </box>
          </geometry>
          <max_contacts>10</max_contacts>
          <surface>
            <contact>
              <ode/>
            </contact>
            <bounce/>
            <friction>
              <torsional>
                <ode/>
              </torsional>
              <ode/>
            </friction>
          </surface>
        </collision>
        <collision name='base_footprint_fixed_joint_lump__laser_collision_collision_3'>
          <pose>0.103 0 0.116 0 -0 0</pose>
          <geometry>
            <cylinder>
              <length>0.016</length>
              <radius>0.032</radius>
            </cylinder>
          </geometry>
          <max_contacts>10</max_contacts>
          <surface>
            <contact>
              <ode/>
            </contact>
            <bounce/>
            <friction>
              <torsional>
                <ode/>
              </torsional>
              <ode/>
            </friction>
          </surface>
        </collision>
        <visual name='base_footprint_fixed_joint_lump__base_link_visual'>
          <pose>0 0 0 0 -0 1.57</pose>
          <geometry>
            <mesh>
              <scale>1 1 1</scale>
              <uri>model://limo_four_diff/meshes/limo_base.dae</uri>
            </mesh>
          </geometry>
        </visual>
        <visual name='base_footprint_fixed_joint_lump__depth_camera_visual_visual_1'>
          <pose>0.084 0 0.015 0 -0 0</pose>
          <geometry>
            <box>
              <size>0.02 0.06 0.015</size>
            </box>
          </geometry>
        </visual>
        <visual name='base_footprint_fixed_joint_lump__imu_visual_visual_2'>
          <pose>0 0 0.05 0 -0 0</pose>
          <geometry>
            <box>
              <size>0.001 0.001 0.001</size>
            </box>
          </geometry>
        </visual>
        <visual name='base_footprint_fixed_joint_lump__laser_visual_visual_3'>
          <pose>0.103 0 0.116 0 -0 0</pose>
          <geometry>
            <cylinder>
              <length>0.01</length>
              <radius>0.02</radius>
            </cylinder>
          </geometry>
        </visual>
        <sensor name='sensor_camera' type='depth'>
          <always_on>1</always_on>
          <visualize>1</visualize>
          <update_rate>30</update_rate>
          <camera name='limo_camera'>
            <horizontal_fov>1.047</horizontal_fov>
            <image>
              <width>320</width>
              <height>240</height>
            </image>
            <clip>
              <near>0.05</near>
              <far>3.5</far>
            </clip>
          </camera>
          <plugin name='gazebo_ros_depth_camera_sensor' filename='libgazebo_ros_camera.so'>
            <ros>
              <namespace>/limo</namespace>
              <argument>limo_camera/image_raw:=limo_camera/image</argument>
              <argument>limo_camera/image_depth:=limo_camera/depth/camera_image_depth</argument>
              <argument>limo_camera/camera_info:=limo_camera/camera_info_raw</argument>
              <argument>limo_camera/camera_info_depth:=limo_camera/camera_info_depth</argument>
              <argument>limo_camera/points:=limo_camera/camera_points</argument>
            </ros>
            <camera_name>depth_camera_link</camera_name>
            <frame_name>base_footprint</frame_name>
            <hack_baseline>0.07</hack_baseline>
            <min_depth>0.001</min_depth>
          </plugin>
          <pose>0.084 0 0.45 0 -0 0</pose>
        </sensor>
        <gravity>1</gravity>
        <sensor name='twr_imu' type='imu'>
          <always_on>1</always_on>
          <update_rate>100</update_rate>
          <visualize>1</visualize>
          <imu>
            <angular_velocity>
              <x>
                <noise type='gaussian'>
                  <mean>0</mean>
                  <stddev>0.0002</stddev>
                </noise>
              </x>
              <y>
                <noise type='gaussian'>
                  <mean>0</mean>
                  <stddev>0.0002</stddev>
                </noise>
              </y>
              <z>
                <noise type='gaussian'>
                  <mean>0</mean>
                  <stddev>0.0002</stddev>
                </noise>
              </z>
            </angular_velocity>
            <linear_acceleration>
              <x>
                <noise type='gaussian'>
                  <mean>0</mean>
                  <stddev>0.017</stddev>
                </noise>
              </x>
              <y>
                <noise type='gaussian'>
                  <mean>0</mean>
                  <stddev>0.017</stddev>
                </noise>
              </y>
              <z>
                <noise type='gaussian'>
                  <mean>0</mean>
                  <stddev>0.017</stddev>
                </noise>
              </z>
            </linear_acceleration>
            <orientation>
              <x>
                <noise type='gaussian'>
                  <mean>0.0</mean>
                  <stddev>2e-3</stddev>
                </noise>
              </x>
              <y>
                <noise type='gaussian'>
                  <mean>0.0</mean>
                  <stddev>2e-3</stddev>
                </noise>
              </y>
              <z>
                <noise type='gaussian'>
                  <mean>0.0</mean>
                  <stddev>2e-3</stddev>
                </noise>
              </z>
            </orientation>
          </imu>
          <plugin name='two_wheeled_robot_imu' filename='libgazebo_ros_imu_sensor.so'>
            <initial_orientation_as_reference>0</initial_orientation_as_reference>
            <frame_name>base_footprint</frame_name>
            <ros>
              <namespace>/imu</namespace>
              <remapping>~/out:=data</remapping>
            </ros>
          </plugin>
          <pose>0 0 0.05 0 -0 0</pose>
        </sensor>
        <sensor name='laser' type='ray'>
          <always_on>1</always_on>
          <visualize>1</visualize>
          <update_rate>10</update_rate>
          <ray>
            <scan>
              <horizontal>
                <samples>120</samples>
                <resolution>1</resolution>
                <min_angle>-3.14159</min_angle>
                <max_angle>3.14159</max_angle>
              </horizontal>
              <vertical>
                <samples>1</samples>
                <min_angle>0</min_angle>
                <max_angle>0</max_angle>
              </vertical>
            </scan>
            <range>
              <min>0.3</min>
              <max>15</max>
              <resolution>0.015</resolution>
            </range>
            <noise>
              <type>gaussian</type>
              <mean>0</mean>
              <stddev>0.01</stddev>
            </noise>
          </ray>
          <plugin name='scan' filename='libgazebo_ros_ray_sensor.so'>
            <ros>
              <remapping>~/out:=scan</remapping>
            </ros>
            <output_type>sensor_msgs/LaserScan</output_type>
            <frame_name>base_footprint</frame_name>
          </plugin>
          <pose>0.103 0 0.116 0 -0 0</pose>
        </sensor>
        <self_collide>0</self_collide>
        <enable_wind>0</enable_wind>
        <kinematic>0</kinematic>
      </link>
      <joint name='front_left_wheel' type='revolute'>
        <pose relative_to='base_footprint'>0.1 0.065 0.05 0 -0 0</pose>
        <parent>base_footprint</parent>
        <child>front_left_wheel_link</child>
        <axis>
          <xyz>0 1 0</xyz>
          <limit>
            <lower>-1e+16</lower>
            <upper>1e+16</upper>
          </limit>
          <dynamics>
            <spring_reference>0</spring_reference>
            <spring_stiffness>0</spring_stiffness>
          </dynamics>
        </axis>
        <physics>
          <ode>
            <limit>
              <cfm>0</cfm>
              <erp>0.2</erp>
            </limit>
          </ode>
        </physics>
      </joint>
      <link name='front_left_wheel_link'>
        <pose relative_to='front_left_wheel'>0 0 0 0 -0 0</pose>
        <inertial>
          <pose>0 0 0 0 -0 0</pose>
          <mass>0.5</mass>
          <inertia>
            <ixx>0.01055</ixx>
            <ixy>0</ixy>
            <ixz>0</ixz>
            <iyy>0.00075</iyy>
            <iyz>0</iyz>
            <izz>0.01055</izz>
          </inertia>
        </inertial>
        <collision name='front_left_wheel_link_collision'>
          <pose>0 0.0225 0 1.57 -0 0</pose>
          <geometry>
            <cylinder>
              <length>0.045</length>
              <radius>0.045</radius>
            </cylinder>
          </geometry>
          <max_contacts>10</max_contacts>
          <surface>
            <contact>
              <ode/>
            </contact>
            <bounce/>
            <friction>
              <torsional>
                <ode/>
              </torsional>
              <ode/>
            </friction>
          </surface>
        </collision>
        <visual name='front_left_wheel_link_visual'>
          <pose>0 0 0 0 -0 0</pose>
          <geometry>
            <mesh>
              <scale>1 1 1</scale>
              <uri>model://limo_four_diff/meshes/limo_wheel.dae</uri>
            </mesh>
          </geometry>
        </visual>
        <self_collide>0</self_collide>
        <enable_wind>0</enable_wind>
        <kinematic>0</kinematic>
      </link>
      <joint name='front_right_wheel' type='revolute'>
        <pose relative_to='base_footprint'>0.1 -0.065 0.05 3.14159 -0 0</pose>
        <parent>base_footprint</parent>
        <child>front_right_wheel_link</child>
        <axis>
          <xyz>0 -1 0</xyz>
          <limit>
            <lower>-1e+16</lower>
            <upper>1e+16</upper>
          </limit>
          <dynamics>
            <spring_reference>0</spring_reference>
            <spring_stiffness>0</spring_stiffness>
          </dynamics>
        </axis>
        <physics>
          <ode>
            <limit>
              <cfm>0</cfm>
              <erp>0.2</erp>
            </limit>
          </ode>
        </physics>
      </joint>
      <link name='front_right_wheel_link'>
        <pose relative_to='front_right_wheel'>0 0 0 0 -0 0</pose>
        <inertial>
          <pose>0 0 0 0 -0 0</pose>
          <mass>0.5</mass>
          <inertia>
            <ixx>0.01055</ixx>
            <ixy>0</ixy>
            <ixz>0</ixz>
            <iyy>0.00075</iyy>
            <iyz>0</iyz>
            <izz>0.01055</izz>
          </inertia>
        </inertial>
        <collision name='front_right_wheel_link_collision'>
          <pose>0 0.0225 0 1.57 -0 0</pose>
          <geometry>
            <cylinder>
              <length>0.045</length>
              <radius>0.045</radius>
            </cylinder>
          </geometry>
          <max_contacts>10</max_contacts>
          <surface>
            <contact>
              <ode/>
            </contact>
            <bounce/>
            <friction>
              <torsional>
                <ode/>
              </torsional>
              <ode/>
            </friction>
          </surface>
        </collision>
        <visual name='front_right_wheel_link_visual'>
          <pose>0 0 0 0 -0 0</pose>
          <geometry>
            <mesh>
              <scale>1 1 1</scale>
              <uri>model://limo_four_diff/meshes/limo_wheel.dae</uri>
            </mesh>
          </geometry>
        </visual>
        <self_collide>0</self_collide>
        <enable_wind>0</enable_wind>
        <kinematic>0</kinematic>
      </link>
      <joint name='rear_left_wheel' type='revolute'>
        <pose relative_to='base_footprint'>-0.1 0.065 0.05 0 -0 0</pose>
        <parent>base_footprint</parent>
        <child>rear_left_wheel_link</child>
        <axis>
          <xyz>0 1 0</xyz>
          <limit>
            <lower>-1e+16</lower>
            <upper>1e+16</upper>
          </limit>
          <dynamics>
            <spring_reference>0</spring_reference>
            <spring_stiffness>0</spring_stiffness>
          </dynamics>
        </axis>
        <physics>
          <ode>
            <limit>
              <cfm>0</cfm>
              <erp>0.2</erp>
            </limit>
          </ode>
        </physics>
      </joint>
      <link name='rear_left_wheel_link'>
        <pose relative_to='rear_left_wheel'>0 0 0 0 -0 0</pose>
        <inertial>
          <pose>0 0 0 0 -0 0</pose>
          <mass>0.5</mass>
          <inertia>
            <ixx>0.01055</ixx>
            <ixy>0</ixy>
            <ixz>0</ixz>
            <iyy>0.00075</iyy>
            <iyz>0</iyz>
            <izz>0.01055</izz>
          </inertia>
        </inertial>
        <collision name='rear_left_wheel_link_collision'>
          <pose>0 0.0225 0 1.57 -0 0</pose>
          <geometry>
            <cylinder>
              <length>0.045</length>
              <radius>0.045</radius>
            </cylinder>
          </geometry>
          <max_contacts>10</max_contacts>
          <surface>
            <contact>
              <ode/>
            </contact>
            <bounce/>
            <friction>
              <torsional>
                <ode/>
              </torsional>
              <ode/>
            </friction>
          </surface>
        </collision>
        <visual name='rear_left_wheel_link_visual'>
          <pose>0 0 0 0 -0 0</pose>
          <geometry>
            <mesh>
              <scale>1 1 1</scale>
              <uri>model://limo_four_diff/meshes/limo_wheel.dae</uri>
            </mesh>
          </geometry>
        </visual>
        <self_collide>0</self_collide>
        <enable_wind>0</enable_wind>
        <kinematic>0</kinematic>
      </link>
      <joint name='rear_right_wheel' type='revolute'>
        <pose relative_to='base_footprint'>-0.1 -0.065 0.05 3.14159 -0 0</pose>
        <parent>base_footprint</parent>
        <child>rear_right_wheel_link</child>
        <axis>
          <xyz>0 -1 0</xyz>
          <limit>
            <lower>-1e+16</lower>
            <upper>1e+16</upper>
          </limit>
          <dynamics>
            <spring_reference>0</spring_reference>
            <spring_stiffness>0</spring_stiffness>
          </dynamics>
        </axis>
        <physics>
          <ode>
            <limit>
              <cfm>0</cfm>
              <erp>0.2</erp>
            </limit>
          </ode>
        </physics>
      </joint>
      <link name='rear_right_wheel_link'>
        <pose relative_to='rear_right_wheel'>0 0 0 0 -0 0</pose>
        <inertial>
          <pose>0 0 0 0 -0 0</pose>
          <mass>0.5</mass>
          <inertia>
            <ixx>0.01055</ixx>
            <ixy>0</ixy>
            <ixz>0</ixz>
            <iyy>0.00075</iyy>
            <iyz>0</iyz>
            <izz>0.01055</izz>
          </inertia>
        </inertial>
        <collision name='rear_right_wheel_link_collision'>
          <pose>0 0.0225 0 1.57 -0 0</pose>
          <geometry>
            <cylinder>
              <length>0.045</length>
              <radius>0.045</radius>
            </cylinder>
          </geometry>
          <max_contacts>10</max_contacts>
          <surface>
            <contact>
              <ode/>
            </contact>
            <bounce/>
            <friction>
              <torsional>
                <ode/>
              </torsional>
              <ode/>
            </friction>
          </surface>
        </collision>
        <visual name='rear_right_wheel_link_visual'>
          <pose>0 0 0 0 -0 0</pose>
          <geometry>
            <mesh>
              <scale>1 1 1</scale>
              <uri>model://limo_four_diff/meshes/limo_wheel.dae</uri>
            </mesh>
          </geometry>
        </visual>
        <self_collide>0</self_collide>
        <enable_wind>0</enable_wind>
        <kinematic>0</kinematic>
      </link>
      <static>0</static>
      <plugin name='four_diff_controller' filename='libgazebo_ros_diff_drive.so'>
        <update_rate>50</update_rate>
        <num_wheel_pairs>2</num_wheel_pairs>
        <left_joint>front_left_wheel</left_joint>
        <right_joint>front_right_wheel</right_joint>
        <left_joint>rear_left_wheel</left_joint>
        <right_joint>rear_right_wheel</right_joint>
        <wheel_separation>0.172</wheel_separation>
        <wheel_diameter>0.09</wheel_diameter>
        <max_wheel_torque>20</max_wheel_torque>
        <max_wheel_acceleration>1.0</max_wheel_acceleration>
        <command_topic>cmd_vel</command_topic>
        <publish_odom>1</publish_odom>
        <publish_odom_tf>1</publish_odom_tf>
        <publish_wheel_tf>1</publish_wheel_tf>
        <odometry_topic>odom</odometry_topic>
        <odometry_frame>odom</odometry_frame>
        <robot_base_frame>base_footprint</robot_base_frame>
        <odometry_source>1</odometry_source>
        <ros>
          <remapping>odom:=/odometry</remapping>
        </ros>
      </plugin>
      <pose>-0.090872 -0.06012 0 0 -0 0</pose>
    </model>
    <state world_name='default'>
      <sim_time>123 824000000</sim_time>
      <real_time>131 644887316</real_time>
      <wall_time>1730321070 446202812</wall_time>
      <iterations>123824</iterations>
      <model name='ground_plane'>
        <pose>0 0 0 0 -0 0</pose>
        <scale>1 1 1</scale>
        <link name='link'>
          <pose>0 0 0 0 -0 0</pose>
          <velocity>0 0 0 0 -0 0</velocity>
          <acceleration>0 0 0 0 -0 0</acceleration>
          <wrench>0 0 0 0 -0 0</wrench>
        </link>
      </model>
      <model name='limo_four_diff'>
        <pose>-0.09085 -0.060149 -0.004982 1e-06 1e-06 -0.0003</pose>
        <scale>1 1 1</scale>
        <link name='base_footprint'>
          <pose>-0.09085 -0.060149 -0.004982 1e-06 1e-06 -0.0003</pose>
          <velocity>5e-06 -6e-06 9.1e-05 -0.000728 -0.000307 -8e-06</velocity>
          <acceleration>-0.09091 0.224075 0.185914 -1.45522 -0.612812 0.001915</acceleration>
          <wrench>-0.215065 0.530094 0.439818 0 -0 0</wrench>
        </link>
        <link name='front_left_wheel_link'>
          <pose>0.009169 0.004821 0.045018 1e-06 6e-06 -0.0003</pose>
          <velocity>-1.1e-05 2.9e-05 -2.9e-05 -0.000736 -0.000307 -8e-06</velocity>
          <acceleration>-0.024115 0.062656 -0.058353 -1.47229 -0.619674 0.001916</acceleration>
          <wrench>-0.012058 0.031328 -0.029177 0 -0 0</wrench>
        </link>
        <link name='front_right_wheel_link'>
          <pose>0.00913 -0.125179 0.045018 3.14159 0.000523 -0.0003</pose>
          <velocity>-1.2e-05 3.3e-05 0.000312 -0.000725 -0.000274 -8e-06</velocity>
          <acceleration>-0.024735 0.068901 0.624876 -1.44981 -0.585879 0.001982</acceleration>
          <wrench>-0.012367 0.03445 0.312438 0 -0 0</wrench>
        </link>
        <link name='rear_left_wheel_link'>
          <pose>-0.190831 0.004881 0.045018 1e-06 0.000824 -0.0003</pose>
          <velocity>-1.2e-05 3.2e-05 8.5e-05 -0.00072 -0.000255 -6e-06</velocity>
          <acceleration>-0.026023 0.064682 0.169094 -1.43987 -0.566828 0.006085</acceleration>
          <wrench>-0.013011 0.032341 0.084547 0 -0 0</wrench>
        </link>
        <link name='rear_right_wheel_link'>
          <pose>-0.19087 -0.125119 0.045018 3.14159 5.2e-05 -0.0003</pose>
          <velocity>-1.3e-05 3.3e-05 -3e-06 -0.000729 -0.000289 -8e-06</velocity>
          <acceleration>-0.026143 0.065686 -0.005788 -1.45882 -0.586983 0.001957</acceleration>
          <wrench>-0.013072 0.032843 -0.002894 0 -0 0</wrench>
        </link>
      </model>
      <model name='obstacle'>
        <pose>0 0 0 0 -0 0</pose>
        <scale>1 1 1</scale>
        <link name='obstacle'>
          <pose>0 0 0 0 -0 0</pose>
          <velocity>0 0 0 0 -0 0</velocity>
          <acceleration>0 0 0 0 -0 0</acceleration>
          <wrench>0 0 0 0 -0 0</wrench>
        </link>
      </model>
      <model name='turtlebot3_square'>
        <pose>0 0 0 0 -0 0</pose>
        <scale>1 1 1</scale>
        <link name='Wall_0'>
          <pose>0 1.925 0 0 -0 0</pose>
          <velocity>0 0 0 0 -0 0</velocity>
          <acceleration>0 0 0 0 -0 0</acceleration>
          <wrench>0 0 0 0 -0 0</wrench>
        </link>
        <link name='Wall_2'>
          <pose>-1.925 0 0 0 0 -1.5708</pose>
          <velocity>0 0 0 0 -0 0</velocity>
          <acceleration>0 0 0 0 -0 0</acceleration>
          <wrench>0 0 0 0 -0 0</wrench>
        </link>
        <link name='Wall_3'>
          <pose>0 -1.925 0 0 -0 0</pose>
          <velocity>0 0 0 0 -0 0</velocity>
          <acceleration>0 0 0 0 -0 0</acceleration>
          <wrench>0 0 0 0 -0 0</wrench>
        </link>
        <link name='Wall_4'>
          <pose>1.925 0 0 0 -0 1.5708</pose>
          <velocity>0 0 0 0 -0 0</velocity>
          <acceleration>0 0 0 0 -0 0</acceleration>
          <wrench>0 0 0 0 -0 0</wrench>
        </link>
      </model>
      <light name='sun'>
        <pose>0 0 10 0 -0 0</pose>
      </light>
    </state>
  </world>
</sdf>
